Workbook

Sheet wholesale
B1: Single | C1: Double
B2: Door | C2: Doors
A3: Sill and Shoe Options
A5: ADA (Handicap) Sill SPECIFY LOOSE OR ATTACHED | B5: 16 | C5: 18
A6: Sill, Brite Dip Gold (Plus $7.00/Sidelite) | B6: 16 | C6: 23
A7: Shoe, Brite Dip Gold | B7: 7.5 | C7: 11
A8: Prep (Mortise) for Automatic Door Bottom | B8: 84.5
A9: Supply Automatic Door Bottom up to 3/0 | B9: 56.5
A10: Supply Automatic Door Bottom 3/6 | B10: 69.5
A11: Oak Threshold and Sill, (Plus $20.00/Sidelite) 4 5/8" Jambs Only | B11: 52.5 | C11: 80.5
A12: Oak Threshold and Sill, (Plus $31.00/Sidelite), > 4 5/8" Jambs | B12: 74.5 | C12: 111
A13: Oak Ajustable Sill, (Plus $20.00/Sidelite) | B13: 44 | C13: 88
A15: Misc Options
A16: 2 1/4" Add $129.50 per each Door or Sidelite | B16: 142.5
A17: Prep for Viewer | B17: 21.5
A18: Viewer, Supply and Install, US3, US10B, US26D | B18: 36
A19: Mail slot cut out only | B19: 52
A20: Lite or Louvre Vent, Install (Supplied by Customer) | B20: 52
A21: Pet Door, Cut out only, (Door or specs supplied by customer) | B21: 52
A22: Pet Door Cut Out and Install (Supplied by Customer) | B22: 74.5
A23: Stucco Molding (Supplied by Customer), Install | B23: 23 | C23: 30.5
A24: Custom Mullions for Non-Std Openings CALL FOR QUOTE per mullion | B24: 77 | C24: MINIMUM
A25: Dutch Doors + Any Needed Custom Woodwork | B25: 96.5 | C25: MINIMUM
A26: FJ Jambs on all 4 sides | B26: N/C
A27: Mantel or Dentil Shelf, Install | B27: 44 | C27: 88
A28: Composite and Auralast Frames | B28: 72 | C28: 94
A29: Double Rabbet Jamb (for Screen or Storm Door) | B29: 69.5
A30: Install Customer Supplied Glass | B30: 77
A31: Outswing Aluminum Astragal w/ Astragal Cap 6/8 or 8/0 Doors | C31: 66
A33: Deductions from Standard Charge For:
A34: No Sill | B34: -15 | C34: -24
A35: No Shoe | B35: -5 | C35: -11
A36: No Weatherstrip | B36: -13 | C36: -24
A37: No T-Astragal | C37: -13
A38: No Flushbolts, each. | C38: -22
A40: Hinge Finish Key
A42: Bright Brass US3 Oil Rubbed Bronze US10B Polished Chrome | C42: US26D
A43: Satin (Dull) Brass US4 Satin Nickel US15 Satin Chrome | C43: US26D
A44: Antique Brass US5 Antique Nickel US15A Stainless Steel,Satin | C44: US32D
A45: Black L1
...

Sheet retail
B1: Single | C1: Double
B2: Door | C2: Doors
A3: Sill and Shoe Options
A5: ADA (Handicap) Sill SPECIFY LOOSE OR ATTACHED | B5: =wholesale!B5*2 | C5: =wholesale!C5*2
A6: Sill, Brite Dip Gold (Plus $14.00/Sidelite) | B6: =wholesale!B6*2 | C6: =wholesale!C6*2
A7: Shoe, Brite Dip Gold | B7: =wholesale!B7*2 | C7: =wholesale!C7*2
A8: Prep (Mortise) for Automatic Door Bottom | B8: =wholesale!B8*2
A9: Supply Automatic Door Bottom up to 3/0 | B9: =wholesale!B9*2
A10: Supply Automatic Door Bottom 3/6 | B10: =wholesale!B10*2
A11: Oak Threshold and Sill, (Plus $40.00/Sidelite) 4 5/8" Jambs Only | B11: =wholesale!B11*2 | C11: =wholesale!C11*2
A12: Oak Threshold and Sill, (Plus $62.00/Sidelite), > 4 5/8" Jambs | B12: =wholesale!B12*2 | C12: =wholesale!C12*2
A13: Oak Ajustable Sill, (Plus $40.00/Sidelite) | B13: =wholesale!B13*2 | C13: =wholesale!C13*2
A15: Misc Options
A16: 2 1/4" Add $258.00 per each Door or sidelite | B16: =wholesale!B16*2
A17: Prep for Viewer | B17: =wholesale!B17*2
A18: Viewer, Supply and Install, US3, US10B, US26D | B18: =wholesale!B18*2
A19: Mail Slot cut out only | B19: =wholesale!B19*2
A20: Lite or Louvre Vent, Install (Supplied by Customer) | B20: =wholesale!B20*2
A21: Pet Door, Cut out only, (Door or specs supplied by customer) | B21: =wholesale!B21*2
A22: Pet Door Cut Out and Install (Supplied by Customer) | B22: =wholesale!B22*2
A23: Stucco Molding (Supplied by Customer), Install | B23: =wholesale!B23*2 | C23: =wholesale!C23*2
A24: Custom Mullions for Non-Std Openings CALL FOR QUOTE per mullion | B24: =wholesale!B24*2 | C24: MINIMUM
A25: Dutch Doors + Any Needed Custom Woodwork | B25: =wholesale!B25*2 | C25: MINIMUM
A26: FJ Jambs on all 4 sides | B26: N/C
A27: Mantel or Dentil Shelf, Install | B27: =wholesale!B27*2 | C27: =wholesale!C27*2
A28: Composite and Auralast Frames | B28: =wholesale!B28*2 | C28: =wholesale!C28*2
A29: Double Rabbet Jamb (for Screen or Storm Door) | B29: =wholesale!B29*2
A30: Install Customer Supplied Glass | B30: =wholesale!B30*2
A31: Outswing Aluminum Astragal w/ Astragal Cap 6/8 or 8/0 Doors | C31: 120
A33: Deductions from Standard Charge For:
A34: No Sill | B34: =wholesale!B34*2 | C34: =wholesale!C34*2
A35: No Shoe | B35: =wholesale!B35*2 | C35: =wholesale!C35*2
A36: No Weatherstrip | B36: =wholesale!B36*2 | C36: =wholesale!C36*2
A37: No T-Astragal | C37: =wholesale!C37*2
A38: No Flushbolts, each. | C38: =wholesale!C38*2
A40: Hinge Finish Key
A42: Bright Brass US3 Oil Rubbed Bronze US10B Polished Chrome | B42: US26
A43: Satin (Dull) Brass US4 Satin Nickel US15 Satin Chrome | B43: US26D
A44: Antique Brass US5 Antique Nickel US15A Stainless Steel,Satin | B44: US32D
A45: Black L1
...
