Workbook

Sheet wholesale
A1: JAMB TYPE | B1: 6/8 SINGLE | C1: 6/8 DOUBLE | D1: 7/0 & 8/0 SINGLE | E1: 7/0 & 8/0 DOUBLE
A2: AND SIZE
A3: PR PINE 4 9/16 | B3: 56.5 | C3: 135 | D3: 89.5 | E3: 156
A4: PR PINE 4 13/16 | B4: 75 | C4: 149.5 | D4: 101.5 | E4: 170
A5: PR PINE 5 1/4 | B5: 73.5 | C5: 149.5 | D5: 101.5 | E5: 170
A6: PR PINE 6 1/2 | B6: 97 | C6: 166.5 | D6: 119 | E6: 183.5
A7: PR PINE 7 1/4 | B7: 107 | C7: 178 | D7: 133 | E7: 201
A9: SG PINE 4 9/16 | B9: 108.5 | C9: 178.5 | D9: 160 | E9: 244.5
A10: SG PINE 4 13/16 | B10: 118.5 | C10: 195.5 | D10: 178.5 | E10: 257.5
A11: SG PINE 5 1/4 | B11: 118.5 | C11: 195.5 | D11: 178.5 | E11: 257.5
A12: SG PINE 6 1/2 | B12: 142 | C12: 221.5 | D12: 200.5 | E12: 279.5
A13: SG PINE 7 1/4 | B13: 155 | C13: 234 | D13: 216 | E13: 290
A15: VG FIR 4 9/16 | B15: 135 | C15: 210.5 | D15: 212 | E15: 294
A16: VG FIR 4 13/16 | B16: 155 | C16: 244.5 | D16: 221.5 | E16: 314
A17: VG FIR 5 1/4 | B17: 155 | C17: 244.5 | D17: 221.5 | E17: 314
A18: VG FIR 7 1/4 | B18: 274.5 | C18: 393
A20: SOL OAK 4 9/16 | B20: 163 | C20: 246 | D20: 227 | E20: 296.5
A21: SOL OAK 5 1/4 | B21: 211 | C21: 265.5 | D21: 267 | E21: 323.5
B23: 6/8 BIPASS | C23: 6/8 BIPASS | D23: 7/0 & 8/0 BIPASS | E23: 7/0 & 8/0 BIPASS
B24: 2 DOOR | C24: 3 DOOR | D24: 2 DOOR | E24: 3 DOOR
A25: PR PINE 4 9/16 | B25: 65.5 | C25: 85 | D25: 87 | E25: 103.5
A26: PR PINE 4 13/16 | B26: 79 | C26: 98.5 | D26: 98.5 | E26: 115
A27: PR PINE 5 1/4 | B27: 79 | C27: 98.5 | D27: 98.5 | E27: 115
A28: PR PINE 6 1/2 | B28: 103.5 | C28: 128 | D28: 128 | E28: 153.5
A29: PR PINE 7 1/4 | B29: 103.5 | C29: 128 | D29: 128 | E29: 153.5
A31: SG PINE 4 9/16 | B31: 107.5 | C31: 120 | D31: 120.5 | E31: 135
A32: SG PINE 5 1/4 | B32: 118.5 | C32: 133 | D32: 133 | E32: 149
A34: VG FIR 4 9/16 | B34: 137 | C34: 158 | D34: 155 | E34: 186.5
A35: VG FIR 5 1/4 | B35: 152.5 | C35: 177 | D35: 169.5 | E35: 202.5
A36: VG FIR 7 1/4 | C36: 223
A37: Bipass with Rectangular Pulls Add: 2-Door 51.00, 3-Door (4 Pulls) 102.00
A39: STANDARD DOOR SPECIFICATIONS & ITEMS SUPPLIED BY A BETTER DOOR
A40: Int. Jambs, Stops & 3 ea. 3 1/2" X 3 1/2" x 1/4"R Satin Br hinges per door for 6/8 and 7/0 doors.
A41: 4 ea. 3 1/2" X 3 1/2" x 1/4"R Satin Br hinges per door for 8/0 doors.
A42: Double Door prices include Ball Catches, add for Astragal and Flush Bolt.
A43: Stain Grade Pine and Vertical Grain Fir jambs may be veneer.
A44: Hinge spacing to be approximately 7" from top of door and 11" from bottom of door.
A45: Middle hinge will be centered between top and bottom hinges.
A46: Door Handle Bore will be 2 1/8" D with a 2 3/8" backset, 44" from the top of the door for 6/8 doors,
A47: 48" for 7/0s and 60" for 8/0 doors.
...

Sheet retail
A1: JAMB TYPE | B1: 6/8 SINGLE | C1: 6/8 DOUBLE | D1: 7/0 & 8/0 SINGLE | E1: 7/0 & 8/0 DOUBLE
A2: AND SIZE
A3: PR PINE 4 9/16 | B3: =wholesale!B3*2 | C3: =wholesale!C3*2 | D3: =wholesale!D3*2 | E3: =wholesale!E3*2
A4: PR PINE 4 13/16 | B4: =wholesale!B4*2 | C4: =wholesale!C4*2 | D4: =wholesale!D5*2 | E4: =wholesale!E4*2
A5: PR PINE 5 1/4 | B5: =wholesale!B5*2 | C5: =wholesale!C5*2 | D5: =wholesale!D5*2 | E5: =wholesale!E5*2
A6: PR PINE 6 1/2 | B6: =wholesale!B6*2 | C6: =wholesale!C6*2 | D6: =wholesale!D6*2 | E6: =wholesale!E6*2
A7: PR PINE 7 1/4 | B7: =wholesale!B7*2 | C7: =wholesale!C7*2 | D7: =wholesale!D7*2 | E7: =wholesale!E7*2
A9: SG PINE 4 9/16 | B9: =wholesale!B9*2 | C9: =wholesale!C9*2 | D9: =wholesale!D9*2 | E9: =wholesale!E9*2
A10: SG PINE 4 13/16 | B10: =wholesale!B10*2 | C10: =wholesale!C10*2 | D10: =wholesale!D11*2 | E10: =wholesale!E10*2
A11: SG PINE 5 1/4 | B11: =wholesale!B11*2 | C11: =wholesale!C11*2 | D11: =wholesale!D11*2 | E11: =wholesale!E11*2
A12: SG PINE 6 1/2 | B12: =wholesale!B12*2 | C12: =wholesale!C12*2 | D12: =wholesale!D12*2 | E12: =wholesale!E12*2
A13: SG PINE 7 1/4 | B13: =wholesale!B13*2 | C13: =wholesale!C13*2 | D13: =wholesale!D13*2 | E13: =wholesale!E13*2
A15: VG FIR 4 9/16 | B15: =wholesale!B15*2 | C15: =wholesale!C15*2 | D15: =wholesale!D15*2 | E15: =wholesale!E15*2
A16: VG FIR 4 13/16 | B16: =wholesale!B16*2 | C16: =wholesale!C16*2 | D16: =wholesale!D16*2 | E16: =wholesale!E16*2
A17: VG FIR 5 1/4 | B17: =wholesale!B17*2 | C17: =wholesale!C17*2 | D17: =wholesale!D17*2 | E17: =wholesale!E17*2
A18: VG FIR 7 1/4 | B18: =wholesale!B18*2 | C18: =wholesale!C18*2
A20: SOL OAK 4 9/16 | B20: =wholesale!B20*2 | C20: =wholesale!C20*2 | D20: =wholesale!D20*2 | E20: =wholesale!E20*2
A21: SOL OAK 5 1/4 | B21: =wholesale!B21*2 | C21: =wholesale!C21*2 | D21: =wholesale!D21*2 | E21: =wholesale!E21*2
B23: 6/8 BIPASS | C23: 6/8 BIPASS | D23: 7/0 & 8/0 BIPASS | E23: 7/0 & 8/0 BIPASS
B24: 2 DOOR | C24: 3 DOOR | D24: 2 DOOR | E24: 3 DOOR
A25: PR PINE 4 9/16 | B25: =wholesale!B25*2 | C25: =wholesale!C25*2 | D25: =wholesale!D25*2 | E25: =wholesale!E25*2
A26: PR PINE 4 13/16 | B26: =wholesale!B26*2 | C26: =wholesale!C26*2 | D26: =wholesale!D26*2 | E26: =wholesale!E26*2
A27: PR PINE 5 1/4 | B27: =wholesale!B27*2 | C27: =wholesale!C27*2 | D27: =wholesale!D27*2 | E27: =wholesale!E27*2
A28: PR PINE 6 1/2 | B28: =wholesale!B28*2 | C28: =wholesale!C28*2 | D28: =wholesale!D28*2 | E28: =wholesale!E28*2
A29: PR PINE 7 1/4 | B29: =wholesale!B29*2 | C29: =wholesale!C29*2 | D29: =wholesale!D29*2 | E29: =wholesale!E29*2
A31: SG PINE 4 9/16 | B31: =wholesale!B31*2 | C31: =wholesale!C31*2 | D31: =wholesale!D31*2 | E31: =wholesale!E31*2
A32: SG PINE 5 1/4 | B32: =wholesale!B32*2 | C32: =wholesale!C32*2 | D32: =wholesale!D32*2 | E32: =wholesale!E32*2
A34: VG FIR 4 9/16 | B34: =wholesale!B34*2 | C34: =wholesale!C34*2 | D34: =wholesale!D34*2 | E34: =wholesale!E34*2
A35: VG FIR 5 1/4 | B35: =wholesale!B35*2 | C35: =wholesale!C35*2 | D35: =wholesale!D35*2 | E35: =wholesale!E35*2
A36: VG FIR 7 1/4 | C36: =wholesale!C36*2
A37: Bipass with Rectangular Pulls Add: 2-Door 102.00 3-Door (4 Pulls) 204.00
A39: STANDARD DOOR SPECIFICATIONS & ITEMS SUPPLIED BY A BETTER DOOR
A40: Int. Jambs, Stops & 3 ea. 3 1/2" X 3 1/2" x 1/4"R Satin Br hinges per door for 6/8 and 7/0 doors.
A41: 4 ea. 3 1/2" X 3 1/2" x 1/4"R Satin Br hinges per door for 8/0 doors.
A42: Double Door prices include Ball Catches, add for Astragal and Flush Bolt.
A43: Stain Grade Pine and Vertical Grain Fir jambs may be veneer.
A44: Hinge spacing to be approximately 7" from top of door and 11" from bottom of door.
A45: Middle hinge will be centered between top and bottom hinges.
A46: Door Handle Bore will be 2 1/8" D with a 2 3/8" backset, 44" from the top of the door for 6/8 doors,
A47: 48" for 7/0s and 60" for 8/0 doors.
...
