Workbook

Sheet wholesale
F1: Single | H1: Double
F2: Door | H2: Doors
A3: Sizing Options
A4: 1 3/4" Door on Interior Jambs | F4: 10.5 | G4: 21 | H4: 20 | I4: 15.5
A5: Rip Jambs to Special Width (Use next larger size) Per Set | F5: 20 | G5: 20 | H5: 19 | I5: 14.5
A6: Rip Door or Sidelite to Special Width - Per Side | F6: 20 | G6: 0
A7: Trim Height of Door or Sidelite-Per Cut | F7: 20 | G7: 0
A8: Cut & Plug HC Door for Height | F8: 52.5 | G8: 0
A9: Cut & Plug HC Door for Width Flush Doors Only, No Molded Doors | F9: 64.5 | G9: 0
A10: Cut & Plug SC Door for Height | F10: 74.5 | G10: 0
A11: Cut & Plug SC Door for Width | F11: 115 | G11: 0
A12: Rip and Edge Kerf | F12: 23 | G12: 0
A13: Customer Supplied Hinges | G13: 0
A14: Handling Charge | F14: 6.5 | G14: 12.5 | H14: 12.5 | I14: 8.5
A16: Hinges, Residential Grade
A18: Install 3 ea 3 1/2"x 3 1/2" US3, US5, US10B, US15, US26, US26D, L1 Black | F18: 8 | G18: 6.5 | H18: 15 | I18: 13
A19: Install 4 ea 3 1/2"x 3 1/2" US3, US5, US10B, US15, US26, US26D, L1 Black | F19: 10 | G19: 8 | H19: 20 | I19: 17
A20: Install 3 ea 4" x 4" US3, US5, US10B, US15, US26, US26D, L1 Black | F20: 10 | G20: 8.5 | H20: 20 | I20: 18
A21: Solid Brass Hinges 3 ea 3 1/2" x 3 1/2" | F21: 26.5 | G21: 23 | H21: 53.5 | I21: 48
A23: Hinges, Commercial Grade Plain Bearing
A25: Install 3 ea 3 1/2"x 3 1/2" US3, US4, US5, US10B, US15, US26, US26D, L1 Black | F25: 20.5 | G25: 18 | H25: 41 | I25: 37
A26: Install 4 ea 3 1/2"x 3 1/2" US3, US4, US5, US10B, US15, US26, US26D, L1 Black | F26: 27 | G26: 23.5 | H26: 54.5 | I26: 49
A27: Install 3 ea 4"x 4" US3, US4, US5, US10B, US15, US26, US26D, L1 Black | F27: 26 | G27: 21 | H27: 52.5 | I27: 44
A28: Install 4 ea 4"x 4" US3, US4, US5, US10B, US15, US26, US26D, L1 Black | F28: 34.5 | G28: 28.5 | H28: 68.5 | I28: 59
A30: Double Swing Floor Hinge
A32: US4 | F32: 76.5 | G32: 67.5
A33: US3, US5, US15, US26D | F33: 105.5 | G33: 91.5
A34: US10B, US26 | F34: 119.5 | G34: 105
A35: Prep for Installation of Double Swing Floor Hinge | F35: 91.5 | G35: 73.5
A37: Other Hinge Options
A39: SOSS Hinges, Cost per hinge | F39: 55.5 | G39: 48 | H39: each
A40: SOSS hinges, prep for installation | F40: 38 | G40: 31 | H40: each
A41: Touch Latch, Installed | F41: 29 | G41: 13 | H41: each
A42: Boring/Mortizing Options
A43: Mortise for Barn Door Guide | F43: 79.5
A44: Bore only 2 1/8" handle or dead bolt | F44: 37 | G44: 7.5
A45: Bore 2 1/8" Round Bypass Pulls (1/2 bore) | F45: 19 | G45: 7.5
A46: Bore Passive Door | H46: 52 | I46: 10
A47: Prep for Pocket Door Handle (Square cut-out in edge of door) | F47: 37 | G47: 19
A48: Mortise for Oval or Rectangular, Emtek, Baldwin, etc. surface pulls, each | F48: 28.5 | G48: 16
...

Sheet retail
F1: Single | G1: Double
F2: Door | G2: Doors
A3: Sizing Options
A4: 1 3/4" Door on Interior Jambs | F4: =wholesale!F4*2 | G4: =wholesale!H4*2
A5: Rip Jambs to Special Width (Use next larger size) Per Set | F5: =wholesale!F5*2 | G5: =wholesale!H5*2
A6: Rip Door or Sidelite to Special Width - Per Side | F6: =wholesale!F6*2
A7: Trim Height of Door or Sidelite-Per Cut | F7: =wholesale!F7*2
A8: Cut & Plug HC Door for Height | F8: =wholesale!F8*2
A9: Cut & Plug HC Door for Width Flush Doors Only, No Molded Doors | F9: =wholesale!F9*2
A10: Cut & Plug SC Door for Height | F10: =wholesale!F10*2
A11: Cut & Plug SC Door for Width | F11: =wholesale!F11*2
A12: Rip Jamb & Edge Kerf | F12: =wholesale!F12*2
A13: Customer Supplied Hinges
A14: Handling Charge | F14: =wholesale!F14*2 | G14: =wholesale!H14*2
A16: Hinges, Residential Grade
A18: Install 3 ea 3 1/2"x 3 1/2" US3, US5, US10B, US15, US26, US26D, L1 Black | F18: =wholesale!F18*2 | G18: =wholesale!H18*2
A19: Install 4 ea 3 1/2"x 3 1/2" US3, US5, US10B, US15, US26, US26D, L1 Black | F19: =wholesale!F19*2 | G19: =wholesale!H19*2
A20: Install 3 ea 4" x 4" US3, US5, US10B, US15, US26, US26D, L1 Black | F20: =wholesale!F20*2 | G20: =wholesale!H20*2
A21: Solid Brass Hinges 3 ea 3 1/2" x 3 1/2" | F21: =wholesale!F21*2 | G21: =wholesale!H21*2
A23: Hinges, Commercial Grade Plain Bearing
A25: Install 3 ea 3 1/2 "x 3 1/2" US3, US4, US5, US10B, US15, US26, US26D, L1 Black | F25: =wholesale!F25*2 | G25: =wholesale!H25*2
A26: Install 4 ea 3 1/2"x 3 1/2" US3, US4, US5, US10B, US15, US26, US26D, L1 Black | F26: =wholesale!F26*2 | G26: =wholesale!H26*2
A27: Install 3 ea 4"x 4" US3, US4, US5, US10B, US15, US26, US26D, L1 Black | F27: =wholesale!F27*2 | G27: =wholesale!H27*2
A28: Install 4 ea 4"x 4" US3, US4, US5, US10B, US15, US26, US26D, L1 Black | F28: =wholesale!F28*2 | G28: =wholesale!H28*2
A30: Double Swing Floor Hinge
A32: US4 | F32: =wholesale!F32*2
A33: US3, US5, US15, US26D | F33: =wholesale!F33*2
A34: US10B, US26 | F34: =wholesale!F34*2
A35: Prep for Installation of Double Swing Floor Hinge | F35: =wholesale!F35*2
A37: Other Hinge Options
A39: SOSS Hinges, Cost per hinge | F39: =wholesale!F39*2 | G39: each
A40: SOSS hinges, prep for installation | F40: =wholesale!F40*2 | G40: each
A41: Touch Latch installed | F41: =wholesale!F41*2 | G41: each
A42: Boring/Mortizing Options
A43: Mortise for Barn Door Guide | F43: =wholesale!F43*2
A44: Bore only 2 1/8" handle or dead bolt | F44: =wholesale!F44*2
A45: Bore 2 1/8" Round Bypass Pulls (1/2 bore) | F45: =wholesale!F45*2
A46: Bore Passive Door | G46: =wholesale!H46*2
A47: Prep for Pocket Door Handle | F47: =wholesale!F47*2
A48: Mortise for Oval or Rectangular, Emtek, Baldwin, etc. surface pulls, each | F48: =wholesale!F48*2
...
