Workbook

Sheet wholesale
B1: Single | D1: Double
B2: Door | D2: Doors
A3: Sizing Options
A4: 2 1/4" Doors, per door or sidelite add: | B4: 142
A5: Rip Jambs to Special Width - Per Door or Sidelite Unit | B5: 20 | D5: 20
A6: Rip, Each Door or Sidelite to Special Width - Per Side | B6: 20
A7: Rip and Edge Kerf - 2 Sides | B7: 23 | D7: 23
A8: Trim Height of Door or Sidelite - Per Cut | B8: 20
A9: Cut and Plug HC Door for Height | B9: 52.5
A10: Cut and Plug HC Door for Width, Flush doors only, No molded doors | B10: 64.5
A11: Cut and Plug SC Door for Height | B11: 74.5
A12: Cut and Plug SC Door for Width | B12: 115
A14: Customer Supplied Hinges
A15: Handling Charge | B15: 6.5 | D15: 12.5
A17: Hinges Residential Grade
A18: Install 3 ea 4"x4" US3, US5, US10B, US15, US26, US26D, L1 Black | B18: 10 | D18: 20
A19: Install 4 ea 4"x4" US3, US5, US10B, US15, US26, US26D, L1 Black | B19: 14 | D19: 27
A20: NRP Upgrade ($3.00 per hinge) | B20: 11 | D20: 22
A21: Install 3 ea 4" x 4" Solid Brass Hinges | B21: 36 | D21: 72
A22: Install 3 ea 4" x 4" Stainless NRP Hinges 11.25 Each | B22: 37.5 | D22: 74.5
A23: Install Spring Hinge 4"x 4" US4, each | B23: 12
A24: Install Spring Hinge 4" x 4"US3, 5, 10B, 15, 15A, 26, 26D, L1 Black each | B24: 13.5
A25: 20 Min Fire Door Hinge Upgrade, 2 Spring Hinges on 6/8 Door | B25: 30
A26: 20 Min Fire Door Hinge Upgrade, 2 Spring Hinges on 8/0 Door | B26: 33
A28: Hinges Commercial Grade, Square Corner
A29: Install 3 ea 4" x 4" Plain Bearing, All finishes | B29: 26 | D29: 51.5
A30: Install 4 ea, 4" x 4"Plain Bearing, All finishes | B30: 34.5 | D30: 68.5
A31: Install 3 ea 4" x 4" Ball Bearing Hinges, US4 | B31: 29.5 | D31: 58
A32: Install 4 ea 4" x 4" Ball Bearing Hinges, US4 | B32: 38 | D32: 76.5
A33: Install 3 ea 4" x 4" Ball Bearing Hinges,US3, 5, 10B, 15, 15A, 26, 26D, L1 Black | B33: 46 | D33: 91.5
A34: Install 4 ea 4" x 4" Ball Bearing Hinges,US3, 5, 10B, 15, 15A, 26, 26D, L1 Black | B34: 61 | D34: 121.5
A35: Spring Hinge, ea, Commercial Grade US3,4,5,10B,15, 15A, 26,26D, L1 Black | B35: 33
A36: NRP upgrade (3 hinges) | B36: 12.5 | D36: 24.5
A37: NRP 3 ea 4" x 4" Plain Bearing, Stainless Steel. 15.00 Each | B37: 50 | D37: 99.5
A38: 20 Min Fire Door Hinge Upgrade, 2 Spring Hinges on 6/8 Door | B38: 75
A39: 20 Min Fire Door Hinge Upgrade 2 Spring Hinges on 8/0 Door | B39: 83.5
A41: Boring & Mortising Options
A42: Mortise Lockset, Baldwin etc. | B42: 131
A43: Prep Passive Door for Mortise Style Trim | B43: 50.5
A44: Bore Passive Door (for standard dummy handle) | D44: 52
...

Sheet retail
B1: Single | C1: Double
B2: Door | C2: Doors
A3: Sizing Options
A4: 2 1/4" Doors, per door or sidelite add: | B4: =wholesale!B4*2
A5: Rip Jambs to Special Width - Per Door or Sidelite Unit | B5: =wholesale!B5*2 | C5: =wholesale!D5*2
A6: Rip, Each Door or Sidelite to Special Width - Per Side | B6: =wholesale!B6*2
A7: Rabbet Jambs for Screen Door | B7: =wholesale!B7*2 | C7: =wholesale!D7*2
A8: Trim Height of Door or Sidelite - Per Cut | B8: =wholesale!B8*2
A9: Cut and Plug HC Door for Height | B9: =wholesale!B9*2
A10: Cut and Plug HC Door for Width, Flush doors only, No molded doors | B10: =wholesale!B10*2
A11: Cut and Plug SC Door for Height | B11: =wholesale!B11*2
A12: Cut and Plug SC Door for Width | B12: =wholesale!B12*2
A14: Customer Supplied Hinges
A15: Handling Charge | B15: =wholesale!B15*2 | C15: =wholesale!D15*2
A17: Hinges Residential Grade
A18: Install 3 ea 4"x4" US3, US5, US10B, US15, US26, US26D, L1 Black | B18: =wholesale!B18*2 | C18: =wholesale!D18*2
A19: Install 4 ea 4"x4" US3, US5, US10B, US15, US26, US26D, L1 Black | B19: =wholesale!B19*2 | C19: =wholesale!D19*2
A20: NRP Upgrade ($6.00 per hinge) | B20: =wholesale!B20*2 | C20: =wholesale!D20*2
A21: Install 3 ea 4" x 4" Solid Brass Hinges | B21: =wholesale!B21*2 | C21: =wholesale!D21*2
A22: Install 3 ea 4" x 4" Stainless NRP Hinges 22.50 Each | B22: =wholesale!B22*2 | C22: =wholesale!D22*2
A23: Install Spring Hinge 4"x 4" US4, each | B23: =wholesale!B23*2
A24: Install Spring Hinge 4" x 4"US3, US5, US10B, US15, RS26, US26D, L1 Black, each | B24: =wholesale!B24*2
A25: 20 Min Fire Door Hinge Upgrade, 2 Spring hinges on 6/8 Door | B25: 54
A26: 20 Min Fire Door Hinge Upgrade, 2 Spring Hinges on 8/0 Door | B26: 60
A28: Hinges Commercial Grade, Square Corner
A29: Install 3 ea 4" x 4" Plain Bearing, All finishes | B29: =wholesale!B29*2 | C29: =wholesale!D29*2
A30: Install 4 ea, 4" x 4"Plain Bearing, All finishes | B30: =wholesale!B30*2 | C30: =wholesale!D30*2
A31: Install 3 ea 4" x 4" Ball Bearing Hinges, US4 | B31: =wholesale!B31*2 | C31: =wholesale!D31*2
A32: Install 4 ea 4" x 4" Ball Bearing Hinges, US4 | B32: =wholesale!B32*2 | C32: =wholesale!D32*2
A33: Install 3 ea 4" x 4" Ball Bearing Hinges,US3, US5, 10B, 15, 15A, 26, 26D, L1 Black | B33: =wholesale!B33*2 | C33: =wholesale!D33*2
A34: Install 4 ea 4" x 4" Ball Bearing Hinges,US3, US5, 10B, 15, 15A, 26, 26D, L1 Black | B34: =wholesale!B34*2 | C34: 221
A35: Spring Hinge, ea, Commercial Grade US3,4,5,10B,15, 15A, 26,26D, L1 Black | B35: =wholesale!B35*2
A36: NRP upgrade (3 hinges) | B36: 22 | C36: 44
A37: NRP 3 ea 4" x 4" Plain Bearing, Stainless Steel. 30.00 Each | B37: 90 | C37: 180
A38: 20 Min Fire Door Hinge Upgrade, 2 Spring hinges on 6/8 | B38: 136
A39: 20 Min Fire Door Hinge Upgrade, 2 Spring hinges on 8/0 | B39: 151
A42: Boring & Mortising Options
A43: Mortise Lockset, Baldwin etc. | B43: 238
A44: Prep Passive Door for Mortise Style Trim | B44: 91
A45: Bore Passive Door | C45: 94
...
